Workbook

Sheet Most Streamed Spotify Songs 202
A1: Track | B1: Artist | C1: Release Date | D1: Spotify Streams | E1: Spotify Playlist Count | F1: Spotify Popularity | G1: YouTube Views | H1: YouTube Likes | I1: TikTok Views | J1: Apple Music Playlist Count | K1: SiriusXM Spins | L1: Explicit Track | M1: Date Grouped | P1: Source transparency | S1: Nidula Elgiriyewithana. (2024). Most Streamed Spotify Songs 2024. Kaggle.Com. https://www.kaggle.com/datasets/nelgiriyewithana/most-streamed-spotify-songs-2024
A2: MILLION DOLLAR BABY | B2: Tommy Richman | C2: 45408 | D2: 390470936 | E2: 30716 | F2: 92 | G2: 84274754 | H2: 1713126 | I2: 5332281936 | J2: 210 | K2: 684 | L2: 0 | M2: =IF(YEAR(C2)<2010,"Before 2010",IF(YEAR(C2)<=2020,"2010-2020","After 2020")) -> After 2020 | P2: We downloaded this data set from Kaggle.
A3: Not Like Us | B3: Kendrick Lamar | C3: 45416 | D3: 323703884 | E3: 28113 | F3: 92 | G3: 116347040 | H3: 3486739 | I3: 208339025 | J3: 188 | K3: 3 | L3: 1 | M3: =IF(YEAR(C3)<2010,"Before 2010",IF(YEAR(C3)<=2020,"2010-2020","After 2020")) -> After 2020 | P3: https://www.kaggle.com/datasets/nelgiriyewithana/most-streamed-spotify-songs-2024
A4: i like the way you kiss me | B4: Artemas | C4: 45370 | D4: 601309283 | E4: 54331 | F4: 92 | G4: 122599116 | H4: 2228730 | I4: 3369120610 | J4: 190 | K4: 536 | L4: 0 | M4: =IF(YEAR(C4)<2010,"Before 2010",IF(YEAR(C4)<=2020,"2010-2020","After 2020")) -> After 2020
A5: Flowers | B5: Miley Cyrus | C5: 44938 | D5: 2031280633 | E5: 269802 | F5: 85 | G5: 1096100899 | H5: 10629796 | I5: 14603725994 | J5: 394 | K5: 2182 | L5: 0 | M5: =IF(YEAR(C5)<2010,"Before 2010",IF(YEAR(C5)<=2020,"2010-2020","After 2020")) -> After 2020 | P5: Key variable = | Q5: TikTok views
A6: Houdini | B6: Eminem | C6: 45443 | D6: 107034922 | E6: 7223 | F6: 88 | G6: 77373957 | H6: 3670188 | J6: 182 | K6: 1 | L6: 1 | M6: =IF(YEAR(C6)<2010,"Before 2010",IF(YEAR(C6)<=2020,"2010-2020","After 2020")) -> After 2020
A7: Lovin On Me | B7: Jack Harlow | C7: 45240 | D7: 670665438 | E7: 105892 | F7: 83 | G7: 131148091 | H7: 1392593 | I7: 2938686633 | J7: 138 | K7: 4654 | L7: 1 | M7: =IF(YEAR(C7)<2010,"Before 2010",IF(YEAR(C7)<=2020,"2010-2020","After 2020")) -> After 2020
A8: Beautiful Things | B8: Benson Boone | C8: 45309 | D8: 900158751 | E8: 73118 | F8: 86 | G8: 308723145 | H8: 4120760 | I8: 534915313 | J8: 280 | K8: 429 | L8: 0 | M8: =IF(YEAR(C8)<2010,"Before 2010",IF(YEAR(C8)<=2020,"2010-2020","After 2020")) -> After 2020 | P8: Roles
A9: Gata Only | B9: FloyyMenor | C9: 45324 | D9: 675079153 | E9: 40094 | F9: 92 | G9: 228382568 | H9: 1439495 | I9: 3804584163 | J9: 160 | K9: 30 | L9: 1 | M9: =IF(YEAR(C9)<2010,"Before 2010",IF(YEAR(C9)<=2020,"2010-2020","After 2020")) -> After 2020 | P9: Julia | Q9: My role in this data was finding the data set and creating the new variable for the date grouping.
A10: Danza Kuduro - Cover | B10: MUSIC LAB JPN | C10: 45452 | D10: 1653018119 | E10: 1 | L10: 1 | M10: =IF(YEAR(C10)<2010,"Before 2010",IF(YEAR(C10)<=2020,"2010-2020","After 2020")) -> After 2020 | P10: Jordan | Q10: I helped choose the variables that we decided to focus on in the data set.
A11: BAND4BAND (feat. Lil Baby) | B11: Central Cee | C11: 45435 | D11: 90676573 | E11: 10400 | F11: 86 | G11: 32735244 | H11: 988682 | I11: 974656200 | J11: 191 | K11: 117 | L11: 1 | M11: =IF(YEAR(C11)<2010,"Before 2010",IF(YEAR(C11)<=2020,"2010-2020","After 2020")) -> After 2020 | P11: Arham | Q11: My role in this project was to create an idea for our project using music data and confirm the variables we are using for our analysis
A12: I Had Some Help (feat. Morgan Wallen) | B12: Post Malone | C12: 45422 | D12: 250080413 | E12: 16219 | F12: 91 | G12: 32229063 | H12: 550191 | I12: 2100000 | J12: 157 | K12: 71 | L12: 1 | M12: =IF(YEAR(C12)<2010,"Before 2010",IF(YEAR(C12)<=2020,"2010-2020","After 2020")) -> After 2020
A13: The Door | B13: Teddy Swims | C13: 45457 | D13: 111155129 | E13: 2 | L13: 1 | M13: =IF(YEAR(C13)<2010,"Before 2010",IF(YEAR(C13)<=2020,"2010-2020","After 2020")) -> After 2020
A14: LUNCH | B14: Billie Eilish | C14: 45429 | D14: 221636195 | E14: 13800 | F14: 92 | G14: 40022524 | H14: 1307290 | I14: 360017000 | J14: 244 | K14: 45 | L14: 0 | M14: =IF(YEAR(C14)<2010,"Before 2010",IF(YEAR(C14)<=2020,"2010-2020","After 2020")) -> After 2020
A15: Like That | B15: Future | C15: 45373 | D15: 355186436 | E15: 43025 | F15: 88 | G15: 98081493 | H15: 1456177 | J15: 153 | K15: 3 | L15: 1 | M15: =IF(YEAR(C15)<2010,"Before 2010",IF(YEAR(C15)<=2020,"2010-2020","After 2020")) -> After 2020 | P15: Motivation and Goal | Q15: Initially, we chose to decipher a data set about music analytics because of the practical real world use of the music industry. More or less, everyone is interested in many aspects of music, including creation and consumption. Our purpose of choosing Tiktok analytics as our main variable is due to the emergence of the application as a tool to promote new artists/music, compared to other older social media platforms. We are interested in finding out the relationship between platforms such as Instagram, Soundcloud, and spotify against Tiktok and see what viable relationships we can understand from reading the patterns existing in our data set.
A16: bathroom floor | B16: Kids With Buns | C16: 44841 | D16: 297185 | E16: 277 | F16: 12 | G16: 6736502312 | H16: 16785489 | I16: 22234 | J16: 1 | L16: 0 | M16: =IF(YEAR(C16)<2010,"Before 2010",IF(YEAR(C16)<=2020,"2010-2020","After 2020")) -> After 2020
A17: LALA | B17: Myke Towers | C17: 45007 | D17: 925655569 | E17: 103605 | F17: 79 | G17: 934302031 | H17: 4294166 | I17: 7499234052 | J17: 94 | K17: 228 | L17: 1 | M17: =IF(YEAR(C17)<2010,"Before 2010",IF(YEAR(C17)<=2020,"2010-2020","After 2020")) -> After 2020
A18: Fortnight (feat. Post Malone) | B18: Taylor Swift | C18: 45400 | D18: 395433400 | E18: 12784 | F18: 89 | G18: 104673836 | H18: 2484083 | I18: 207317000 | J18: 221 | K18: 3 | L18: 0 | M18: =IF(YEAR(C18)<2010,"Before 2010",IF(YEAR(C18)<=2020,"2010-2020","After 2020")) -> After 2020 | O18: =MIN(D2:D4593) -> 1071
A19: greedy | B19: Tate McRae | C19: 45183 | D19: 1258569694 | E19: 105218 | F19: 87 | G19: 141646818 | H19: 1514837 | I19: 5456156211 | J19: 207 | K19: 3310 | L19: 1 | M19: =IF(YEAR(C19)<2010,"Before 2010",IF(YEAR(C19)<=2020,"2010-2020","After 2020")) -> After 2020
A20: BLUE | B20: Billie Eilish | C20: 45429 | D20: 91272461 | E20: 6499 | F20: 86 | G20: 16038053 | H20: 569377 | I20: 1225345800 | J20: 76 | K20: 1 | L20: 0 | M20: =IF(YEAR(C20)<2010,"Before 2010",IF(YEAR(C20)<=2020,"2010-2020","After 2020")) -> After 2020
A21: As It Was | B21: Harry Styles | C21: 44651 | D21: 3301814535 | E21: 407119 | F21: 87 | G21: 800899315 | H21: 9101589 | I21: 15405881843 | J21: 455 | K21: 4909 | L21: 0 | M21: =IF(YEAR(C21)<2010,"Before 2010",IF(YEAR(C21)<=2020,"2010-2020","After 2020")) -> After 2020
A22: Paint The Town Red | B22: Doja Cat | C22: 45142 | D22: 1065399331 | E22: 170890 | F22: 78 | G22: 240970670 | H22: 2749668 | I22: 7095564106 | J22: 158 | K22: 273 | L22: 1 | M22: =IF(YEAR(C22)<2010,"Before 2010",IF(YEAR(C22)<=2020,"2010-2020","After 2020")) -> After 2020
A23: Espresso | B23: Sabrina Carpenter | C23: 45394 | D23: 547882871 | E23: 24425 | F23: 95 | G23: 107550212 | H23: 1825761 | I23: 1379499000 | J23: 298 | K23: 236 | L23: 1 | M23: =IF(YEAR(C23)<2010,"Before 2010",IF(YEAR(C23)<=2020,"2010-2020","After 2020")) -> After 2020
A24: Danza Kuduro - Cover | B24: MUSIC LAB JPN | C24: 45433 | D24: 1655575417 | E24: 10 | L24: 1 | M24: =IF(YEAR(C24)<2010,"Before 2010",IF(YEAR(C24)<=2020,"2010-2020","After 2020")) -> After 2020
A25: TEXAS HOLD 'EM | B25: Beyoncï¿ | C25: 45332 | D25: 426700979 | E25: 34044 | F25: 86 | G25: 35724356 | H25: 437980 | I25: 6518604175 | J25: 159 | K25: 257 | L25: 1 | M25: =IF(YEAR(C25)<2010,"Before 2010",IF(YEAR(C25)<=2020,"2010-2020","After 2020")) -> After 2020
A26: Future | B26: official sound studio | C26: 45301 | E26: 1 | I26: 4306269694 | L26: 0 | M26: =IF(YEAR(C26)<2010,"Before 2010",IF(YEAR(C26)<=2020,"2010-2020","After 2020")) -> After 2020
A27: Beat Automotivo Tan Tan Tan Viral | B27: WZ Beat | C27: 44705 | D27: 7382759 | E27: 3504 | F27: 35 | G27: 4233958 | H27: 69990 | I27: 22918660728 | J27: 1 | K27: 439 | L27: 0 | M27: =IF(YEAR(C27)<2010,"Before 2010",IF(YEAR(C27)<=2020,"2010-2020","After 2020")) -> After 2020
A28: STAY (with Justin Bieber) | B28: The Kid LAROI | C28: 44386 | D28: 3107100349 | E28: 451732 | F28: 78 | G28: 1256973582 | H28: 14661425 | I28: 23712377029 | J28: 513 | K28: 4096 | L28: 1 | M28: =IF(YEAR(C28)<2010,"Before 2010",IF(YEAR(C28)<=2020,"2010-2020","After 2020")) -> After 2020
A29: Baby Shark | B29: Pinkfong | C29: 42339 | D29: 720822868 | E29: 60945 | F29: 71 | G29: 16322756555 | H29: 48757673 | I29: 6577639193 | J29: 33 | K29: 142 | L29: 0 | M29: =IF(YEAR(C29)<2010,"Before 2010",IF(YEAR(C29)<=2020,"2010-2020","After 2020")) -> 2010-2020
A30: we can't be friends (wait for your love) | B30: Ariana Grande | C30: 45359 | D30: 591068364 | E30: 26203 | F30: 87 | G30: 156882014 | H30: 3080503 | J30: 194 | K30: 32 | L30: 0 | M30: =IF(YEAR(C30)<2010,"Before 2010",IF(YEAR(C30)<=2020,"2010-2020","After 2020")) -> After 2020
A31: Numb / Encore | B31: JAY-Z | C31: 45394 | D31: 1003215671 | E31: 128 | L31: 1 | M31: =IF(YEAR(C31)<2010,"Before 2010",IF(YEAR(C31)<=2020,"2010-2020","After 2020")) -> After 2020
A32: Danza Kuduro - Cover | B32: LOVE BGM JPN | C32: 45426 | D32: 1645079292 | L32: 1 | M32: =IF(YEAR(C32)<2010,"Before 2010",IF(YEAR(C32)<=2020,"2010-2020","After 2020")) -> After 2020
A33: SHEESH | B33: BABYMONSTER | C33: 45383 | D33: 124893397 | E33: 3479 | F33: 82 | G33: 359896095 | H33: 4907193 | I33: 390081328 | J33: 36 | K33: 32 | L33: 0 | M33: =IF(YEAR(C33)<2010,"Before 2010",IF(YEAR(C33)<=2020,"2010-2020","After 2020")) -> After 2020
A34: Water | B34: Tyla | C34: 45135 | D34: 670376179 | E34: 98450 | F34: 83 | G34: 265180930 | H34: 2566846 | I34: 3932956380 | J34: 225 | K34: 1215 | L34: 0 | M34: =IF(YEAR(C34)<2010,"Before 2010",IF(YEAR(C34)<=2020,"2010-2020","After 2020")) -> After 2020
A35: Strangers | B35: Kenya Grace | C35: 45170 | D35: 750154960 | E35: 139141 | F35: 79 | G35: 118208096 | H35: 1495758 | I35: 2231749390 | J35: 163 | K35: 856 | L35: 0 | M35: =IF(YEAR(C35)<2010,"Before 2010",IF(YEAR(C35)<=2020,"2010-2020","After 2020")) -> After 2020
A36: Too Sweet | B36: Hozier | C36: 45373 | D36: 532012790 | E36: 23557 | G36: 62123098 | H36: 923733 | J36: 221 | K36: 64 | L36: 0 | M36: =IF(YEAR(C36)<2010,"Before 2010",IF(YEAR(C36)<=2020,"2010-2020","After 2020")) -> After 2020
A37: What's Love Got to Do with It - 2023 Remaster | B37: Tina Turner | C37: 45408 | D37: 479417905 | E37: 7 | L37: 0 | M37: =IF(YEAR(C37)<2010,"Before 2010",IF(YEAR(C37)<=2020,"2010-2020","After 2020")) -> After 2020
A38: A Bar Song (Tipsy) | B38: Shaboozey | C38: 45394 | D38: 311928522 | E38: 25766 | F38: 96 | G38: 62694868 | H38: 837616 | I38: 378313942 | J38: 149 | K38: 141 | L38: 1 | M38: =IF(YEAR(C38)<2010,"Before 2010",IF(YEAR(C38)<=2020,"2010-2020","After 2020")) -> After 2020
A39: Lose Control | B39: Teddy Swims | C39: 45100 | D39: 775135157 | E39: 88239 | F39: 87 | G39: 139180960 | H39: 1504385 | I39: 597513595 | J39: 215 | K39: 162 | L39: 0 | M39: =IF(YEAR(C39)<2010,"Before 2010",IF(YEAR(C39)<=2020,"2010-2020","After 2020")) -> After 2020
A40: fukumean | B40: Gunna | C40: 45092 | D40: 759998727 | E40: 188142 | F40: 80 | G40: 94699547 | H40: 1222012 | I40: 3281790327 | J40: 123 | K40: 4003 | L40: 1 | M40: =IF(YEAR(C40)<2010,"Before 2010",IF(YEAR(C40)<=2020,"2010-2020","After 2020")) -> After 2020
...

Sheet Cleaned Data
A1: Track | B1: Artist | C1: Release Date | D1: Spotify Streams | E1: Spotify Playlist Count | F1: Spotify Popularity | G1: YouTube Views | H1: YouTube Likes | I1: TikTok Views | J1: Apple Music Playlist Count | K1: SiriusXM Spins | L1: Explicit Track | M1: Date Grouped
A2: MILLION DOLLAR BABY | B2: Tommy Richman | C2: 45408 | D2: 390470936 | E2: 30716 | F2: 92 | G2: 84274754 | H2: 1713126 | I2: 5332281936 | J2: 210 | K2: 684 | L2: 0 | M2: After 2020
A3: Not Like Us | B3: Kendrick Lamar | C3: 45416 | D3: 323703884 | E3: 28113 | F3: 92 | G3: 116347040 | H3: 3486739 | I3: 208339025 | J3: 188 | K3: 3 | L3: 1 | M3: After 2020
A4: i like the way you kiss me | B4: Artemas | C4: 45370 | D4: 601309283 | E4: 54331 | F4: 92 | G4: 122599116 | H4: 2228730 | I4: 3369120610 | J4: 190 | K4: 536 | L4: 0 | M4: After 2020 | P4: =MIN(D2:D2135) -> 301362
A5: Flowers | B5: Miley Cyrus | C5: 44938 | D5: 2031280633 | E5: 269802 | F5: 85 | G5: 1096100899 | H5: 10629796 | I5: 14603725994 | J5: 394 | K5: 2182 | L5: 0 | M5: After 2020
A6: Lovin On Me | B6: Jack Harlow | C6: 45240 | D6: 670665438 | E6: 105892 | F6: 83 | G6: 131148091 | H6: 1392593 | I6: 2938686633 | J6: 138 | K6: 4654 | L6: 1 | M6: After 2020
A7: Beautiful Things | B7: Benson Boone | C7: 45309 | D7: 900158751 | E7: 73118 | F7: 86 | G7: 308723145 | H7: 4120760 | I7: 534915313 | J7: 280 | K7: 429 | L7: 0 | M7: After 2020
A8: Gata Only | B8: FloyyMenor | C8: 45324 | D8: 675079153 | E8: 40094 | F8: 92 | G8: 228382568 | H8: 1439495 | I8: 3804584163 | J8: 160 | K8: 30 | L8: 1 | M8: After 2020
A9: BAND4BAND (feat. Lil Baby) | B9: Central Cee | C9: 45435 | D9: 90676573 | E9: 10400 | F9: 86 | G9: 32735244 | H9: 988682 | I9: 974656200 | J9: 191 | K9: 117 | L9: 1 | M9: After 2020
A10: I Had Some Help (feat. Morgan Wallen) | B10: Post Malone | C10: 45422 | D10: 250080413 | E10: 16219 | F10: 91 | G10: 32229063 | H10: 550191 | I10: 2100000 | J10: 157 | K10: 71 | L10: 1 | M10: After 2020
A11: LUNCH | B11: Billie Eilish | C11: 45429 | D11: 221636195 | E11: 13800 | F11: 92 | G11: 40022524 | H11: 1307290 | I11: 360017000 | J11: 244 | K11: 45 | L11: 0 | M11: After 2020
A12: LALA | B12: Myke Towers | C12: 45007 | D12: 925655569 | E12: 103605 | F12: 79 | G12: 934302031 | H12: 4294166 | I12: 7499234052 | J12: 94 | K12: 228 | L12: 1 | M12: After 2020
A13: Fortnight (feat. Post Malone) | B13: Taylor Swift | C13: 45400 | D13: 395433400 | E13: 12784 | F13: 89 | G13: 104673836 | H13: 2484083 | I13: 207317000 | J13: 221 | K13: 3 | L13: 0 | M13: After 2020
A14: greedy | B14: Tate McRae | C14: 45183 | D14: 1258569694 | E14: 105218 | F14: 87 | G14: 141646818 | H14: 1514837 | I14: 5456156211 | J14: 207 | K14: 3310 | L14: 1 | M14: After 2020
A15: BLUE | B15: Billie Eilish | C15: 45429 | D15: 91272461 | E15: 6499 | F15: 86 | G15: 16038053 | H15: 569377 | I15: 1225345800 | J15: 76 | K15: 1 | L15: 0 | M15: After 2020
A16: As It Was | B16: Harry Styles | C16: 44651 | D16: 3301814535 | E16: 407119 | F16: 87 | G16: 800899315 | H16: 9101589 | I16: 15405881843 | J16: 455 | K16: 4909 | L16: 0 | M16: After 2020
... A322: All of Me | B322: John Legend | C322: 40909 | D322: 2382407025 | E322: 259202 | F322: 80 | G322: 3064193777 | H322: 17820289 | I322: 643209321 | J322: 295 | K322: 341 | L322: 0 | M322: 2010-2020
A323: 2055 | B323: Sleepy Hallow | C323: 44300 | D323: 811700245 | E323: 195603 | F323: 77 | G323: 168936854 | H323: 1450642 | I323: 752325431 | J323: 39 | K323: 232 | L323: 1 | M323: After 2020
A324: Bandit | B324: Don Toliver | C324: 45323 | D324: 152597421 | E324: 19834 | F324: 12 | G324: 6556571 | H324: 181948 | I324: 98100600 | J324: 27 | K324: 1312 | L324: 1 | M324: After 2020
A325: Redbone | B325: Childish Gambino | C325: 42691 | D325: 1615152539 | E325: 377159 | F325: 76 | G325: 887924965 | H325: 7755679 | I325: 430258743 | J325: 271 | K325: 137 | L325: 1 | M325: 2010-2020
A326: You Proof | B326: Morgan Wallen | C326: 44694 | D326: 644437397 | E326: 64367 | F326: 79 | G326: 141964689 | H326: 814824 | I326: 327463451 | J326: 49 | K326: 301 | L326: 0 | M326: After 2020
A327: Break My Heart | B327: Dua Lipa | C327: 43915 | D327: 1198689895 | E327: 130486 | F327: 71 | G327: 761387435 | H327: 6874611 | I327: 1509626629 | J327: 203 | K327: 348 | L327: 0 | M327: 2010-2020
A328: Shut Down | B328: BLACKPINK | C328: 44820 | D328: 654818451 | E328: 39852 | F328: 67 | G328: 633781726 | H328: 11421404 | I328: 3365539262 | J328: 34 | K328: 201 | L328: 0 | M328: After 2020
A329: MIA (feat. Drake) | B329: Bad Bunny | C329: 43384 | D329: 1318254846 | E329: 159832 | F329: 71 | G329: 1572511545 | H329: 8633372 | I329: 244589825 | J329: 163 | K329: 100 | L329: 0 | M329: 2010-2020
A330: Toosie Slide | B330: Drake | C330: 43924 | D330: 1059262917 | E330: 200623 | F330: 64 | G330: 507137305 | H330: 5604031 | I330: 3734881670 | J330: 146 | K330: 31 | L330: 1 | M330: 2010-2020
A331: MIENTRAS ME CURO DEL CORA | B331: KAROL G | C331: 44981 | D331: 426341106 | E331: 29511 | F331: 76 | G331: 304538874 | H331: 2238586 | I331: 871654140 | J331: 22 | K331: 131 | L331: 0 | M331: After 2020
A332: Ballin' (with Roddy Ricch) | B332: Mustard | C332: 43644 | D332: 907346612 | E332: 200091 | F332: 69 | G332: 372311322 | H332: 3400085 | I332: 245290801 | J332: 91 | K332: 34 | L332: 1 | M332: 2010-2020
A333: Ain't No Love In Oklahoma (From Twisters: The Album) | B333: Luke Combs | C333: 45428 | D333: 33661899 | E333: 3565 | F333: 79 | G333: 3729783 | H333: 62696 | I333: 1441200 | J333: 8 | K333: 1 | L333: 0 | M333: After 2020
A334: Vegas (From the Original Motion Picture Soundtrack ELVIS) | B334: Doja Cat | C334: 44687 | D334: 553783547 | E334: 83450 | F334: 68 | G334: 238368386 | H334: 2671201 | I334: 2994040421 | J334: 57 | K334: 1832 | L334: 1 | M334: After 2020
A335: El Merengue | B335: Marshmello | C335: 44988 | D335: 528420867 | E335: 59791 | F335: 75 | G335: 211317309 | H335: 842146 | I335: 451806178 | J335: 84 | K335: 117 | L335: 0 | M335: After 2020
... A599: Rain On Me (with Ariana Grande) | B599: Lady Gaga | C599: 43973 | D599: 1060378159 | E599: 104647 | F599: 68 | G599: 514581598 | H599: 6465409 | I599: 538854965 | J599: 320 | K599: 438 | L599: 0 | M599: 2010-2020
A600: 0.44097222 | B600: Tiï¿½ï¿ | C600: 44868 | D600: 539802784 | E600: 82093 | F600: 74 | G600: 94379586 | H600: 652780 | I600: 119710596 | J600: 187 | K600: 265 | L600: 0 | M600: After 2020
A601: One Right Now (with The Weeknd) | B601: Post Malone | C601: 44505 | D601: 631789333 | E601: 99512 | F601: 65 | G601: 182180447 | H601: 1908939 | I601: 181078488 | J601: 89 | K601: 1005 | L601: 1 | M601: After 2020
A602: A Thousand Years | B602: Christina Perri | C602: 40834 | D602: 1654956613 | E602: 177834 | F602: 77 | G602: 2989286684 | H602: 19870174 | I602: 8594414469 | J602: 94 | K602: 66 | L602: 0 | M602: 2010-2020
A603: Secreto | B603: Anuel AA | C603: 43480 | D603: 759388276 | E603: 68502 | F603: 65 | G603: 1595484197 | H603: 8161642 | I603: 543804719 | J603: 40 | K603: 15 | L603: 0 | M603: 2010-2020
A604: I Hate U | B604: SZA | C604: 44533 | D604: 456871037 | E604: 71261 | F604: 66 | G604: 142820854 | H604: 1393679 | I604: 1676387442 | J604: 105 | K604: 1324 | L604: 1 | M604: After 2020
A605: Better Now | B605: Post Malone | C605: 43217 | D605: 1953403531 | E605: 239092 | F605: 74 | G605: 48443287 | H605: 734538 | I605: 97061584 | J605: 144 | K605: 203 | L605: 1 | M605: 2010-2020
A606: Call Me Maybe | B606: Carly Rae Jepsen | C606: 40909 | D606: 1394048309 | E606: 211162 | F606: 77 | G606: 2007334200 | H606: 12223928 | I606: 367016981 | J606: 222 | K606: 967 | L606: 0 | M606: 2010-2020
A607: Piece Of Your Heart | B607: MEDUZA | C607: 43497 | D607: 995452298 | E607: 188608 | F607: 65 | G607: 464369299 | H607: 4586152 | I607: 1282810923 | J607: 255 | K607: 196 | L607: 0 | M607: 2010-2020
A608: Ram Pam Pam | B608: NATTI NATASHA | C608: 44306 | D608: 257167813 | E608: 38896 | F608: 55 | G608: 794011391 | H608: 4280865 | I608: 2167134347 | J608: 69 | K608: 176 | L608: 1 | M608: After 2020
...

Sheet Descriptive Statistics
A1: Descriptive Statistics --- Most Streamed Spotify Songs 2024
A3: Continuous Variables
A4: Variable | B4: Count | C4: Mean | D4: Median | E4: Standard Deviation | F4: Minimum | G4: Maximum | H4: Range
A5: Spotify Playlist Count | B5: =COUNT('Cleaned Data'!D:D) -> 2134 | C5: =ROUND(AVERAGE('Cleaned Data'!D:D),2) -> 6.6516229e+08 | D5: =ROUND(MEDIAN('Cleaned Data'!D:D),2) -> 5.032422e+08 | E5: =STDEV('Cleaned Data'!D:D) -> 5.7500519e+08 | F5: =MIN('Cleaned Data'!D:D) -> 301362 | G5: =MAX('Cleaned Data'!D:D) -> 4281468720 | H5: =G5-F5 -> 4281167358
A6: Spotify Streams | B6: =COUNT('Cleaned Data'!E:E) -> 2134 | C6: =ROUND(AVERAGE('Cleaned Data'!E:E),2) -> 95863.87 | D6: =ROUND(MEDIAN('Cleaned Data'!E:E),2) -> 73852 | E6: =STDEV('Cleaned Data'!E:E) -> 78127.296 | F6: =MIN('Cleaned Data'!E:E) -> 311 | G6: =MAX('Cleaned Data'!E:E) -> 590392 | H6: =G6-F6 -> 590081
A7: Spotify Popularity | B7: =COUNT('Cleaned Data'!F:F) -> 2134 | C7: =ROUND(AVERAGE('Cleaned Data'!F:F),2) -> 67.6 | D7: =ROUND(MEDIAN('Cleaned Data'!F:F),2) -> 69 | E7: =STDEV('Cleaned Data'!F:F) -> 11.389449 | F7: =MIN('Cleaned Data'!F:F) -> 1 | G7: =MAX('Cleaned Data'!F:F) -> 96 | H7: =G7-F7 -> 95
A8: Youtude View | B8: =COUNT('Cleaned Data'!G:G) -> 2134 | C8: =ROUND(AVERAGE('Cleaned Data'!G:G),2) -> 5.0413873e+08 | D8: =ROUND(MEDIAN('Cleaned Data'!G:G),2) -> 2.2129037e+08 | E8: =STDEV('Cleaned Data'!G:G) -> 8.0274728e+08 | F8: =MIN('Cleaned Data'!G:G) -> 11512 | G8: =MAX('Cleaned Data'!G:G) -> 16322756555 | H8: =G8-F8 -> 16322745043
A9: Youtude Likes | B9: =COUNT('Cleaned Data'!H:H) -> 2134 | C9: =ROUND(AVERAGE('Cleaned Data'!H:H),2) -> 3885864.1 | D9: =ROUND(MEDIAN('Cleaned Data'!H:H),2) -> 2131983 | E9: =STDEV('Cleaned Data'!H:H) -> 5457870.3 | F9: =MIN('Cleaned Data'!H:H) -> 171 | G9: =MAX('Cleaned Data'!H:H) -> 62311179 | H9: =G9-F9 -> 62311008
A10: Tiktok Views | B10: =COUNT('Cleaned Data'!I:I) -> 2134 | C10: =ROUND(AVERAGE('Cleaned Data'!I:I),2) -> 1.2818925e+09 | D10: =ROUND(MEDIAN('Cleaned Data'!I:I),2) -> 345053448 | E10: =STDEV('Cleaned Data'!I:I) -> 5.3698259e+09 | F10: =MIN('Cleaned Data'!I:I) -> 312 | G10: =MAX('Cleaned Data'!I:I) -> 214843956590 | H10: =G10-F10 -> 214843956278
A11: Apple Music Playlist Count | B11: =COUNT('Cleaned Data'!J:J) -> 2134 | C11: =ROUND(AVERAGE('Cleaned Data'!J:J),2) -> 79.79 | D11: =ROUND(MEDIAN('Cleaned Data'!J:J),2) -> 53 | E11: =STDEV('Cleaned Data'!J:J) -> 82.388389 | F11: =MIN('Cleaned Data'!J:J) -> 1 | G11: =MAX('Cleaned Data'!J:J) -> 859 | H11: =G11-F11 -> 858
A12: SiriusXM Spins | B12: =COUNT('Cleaned Data'!K:K) -> 2134 | C12: =ROUND(AVERAGE('Cleaned Data'!K:K),2) -> 277.19 | D12: =ROUND(MEDIAN('Cleaned Data'!K:K),2) -> 97 | E12: =STDEV('Cleaned Data'!K:K) -> 586.02692 | F12: =MIN('Cleaned Data'!K:K) -> 1 | G12: =MAX('Cleaned Data'!K:K) -> 7098 | H12: =G12-F12 -> 7097
A14: Categorical Variables
A15: Variable | B15: Count | C15: Mode | D15: Number of Categories
A17: Explicit Songs | D17: 2
A18: Not Explicit | B18: 1280 | C18: 0
A19: Explicit | B19: 854
A20: Grand Total | B20: 2134
A22: Dates Grouped | D22: 3
A23: 2010-2020 | B23: 1041
A24: After 2020 | B24: 1042 | C24: After 2020
A25: Before 2010 | B25: 51
A26: Grand Total | B26: 2134

Sheet Frequency Table
A1: Frequency Table --- Most Streamed Spotify Songs 2024
A3: Explicit Track
A4: Category | B4: Count | C4: Relative Frequency
A5: Not Explicit (0) | B5: =COUNTIF('Cleaned Data'!L:L,0) -> 1280 | C5: =B5/B7 -> 0.59981256
A6: Explicit (1) | B6: =COUNTIF('Cleaned Data'!L:L,1) -> 854 | C6: =B6/B7 -> 0.40018744
A7: Total | B7: =SUM(B5+B6) -> 2134 | C7: =SUM(C5:C6) -> 1
A8: This reveals that approximately 60% of the songs are not explicit and 40% are explicit.
A9: Date Grouped (Release Era)
A10: Category | B10: Count | C10: Relative Frequency
A11: Before 2010 | B11: =COUNTIF('Cleaned Data'!$M$2:$M$2135,"Before 2010") -> 51 | C11: =B11/$B$14 -> 0.023898782
A12: 2010-2020 | B12: =COUNTIF('Cleaned Data'!$M$2:$M$2135,"2010-2020") -> 1041 | C12: =B12/$B$14 -> 0.48781631
A13: After 2020 | B13: =COUNTIF('Cleaned Data'!$M$2:$M$2135,"After 2020") -> 1042 | C13: =B13/$B$14 -> 0.48828491
A14: Total | B14: =B11+B12+B13 -> 2134 | C14: =SUM(C11:C13) -> 1
A15: This reveals that the categories After 2020 and 2010-2020 are split almost evenly, with both at approximately 49%.

Sheet Visuals

Sheet Commentary
A1: Assignement 3 Commentary:
A3: Question 1: Overall structure of the data: Are there any missing values, outliers, or surprising distributions? How did you have to clean the data to analyze it?
A5: Question 2: Trends or patterns you observe, if any: (E.g.: Are any categories overly dominant or underrepresented?)
A7: Question 3: Relationships you’re curious about (if any).
A9: Question 4: Initial questions or hypotheses: Based on what you see, what might you want to explore next?
A12: Answer 1: In our initial chart "Most Streamed Spotify songs 2024", several categories included entries which were completely missing from the data set. Our first step to cleaning out our data was to filter out the empty fields and remove some of the columns with highest percentage of missing fields, including: Sirius XM Spins (46% blank) and Tiktok Views (21% blank). We had to therefore drop rows (songs) with any missing variables, leaving our total dataset from 4600 songs to 2134 songs after the data was cleaned up.
A14: Answer 2: Explicit and non-explicit music in the cleaned chart have a balanced split of 40-60%, which is pretty reasonable. The only bias in our data set is against older music (pre-2010), as songs before 2010 are barely represented at 2.4% of the data. Songs from 2010-2020 and post-2020 have an even spread in the data set (48.8% each). This makes sense as the dataset was created around 2024 streaming activity, therefore songs in newer eras should have higher numbers in certain categories, especially Tiktok, since majority of the users on that application are Gen-Z. Older generations, who prefer older generation music, may also resort to different ways of consuming their music opposed from streaming, such as physical record purchases and CDs.
A16: Answer 3: According to the r values from our data set, Tiktok Views surprisingly does not have a strong correlation to the other platforms. The correlation of Tiktok to Spotify streams and Youtube views is almost zero (r = 0.04 and 0.02 respectively). In comparison, Spotify and Youtube have a significantly stronger correlation (r= 0.51). This is very important early sign, as this can prove that a song going viral on Tiktok does not necessarily correlate success in the other platforms.
A18: Answer 4: I am curious to understand further why Tiktok has a low correlation to the other platforms. Some of the questions include:
A20: 1) What are different age groups' preferred method of music consumption: (Physical records, Youtube, Paid Subscription at a Digital Streaming Platform, etc.). Once that data is found, can we see any patterns that may indicate why songs pre-2010 era do not appear in the list as much compared to the other decades. This could also show a correlation between age and our Tiktok view category, as songs specifically catered towards a certain generation might do the best in that particular method of music consumption.
A22: 2) I am still curious to know why Tiktok Views has a low correlation to the other platforms. Do laws skew data for certain platforms? For example, I know Tiktok is completely banned in India, therefore Youtube is the most popular method of music consumption for the younger generations atleast. Any musical artist would then promote their music on Reels instead of Tiktok to attract the Indian crowd, which would obviously skew our data. China on the other hand, only uses Tiktok as an official platform, banning all other platforms in the country.
A24: 3) I want to explore more on why the correlation between Spotify and Youtube is so high. What reasons or connections can we get from these applications? In what countries are these two applications specifically being used the most, and is there any correlation for that data?

Sheet Distribution Analysis
F2: Spotify Streams | H2: Spotify Playlist Count | J2: Spotify Popularity | L2: YouTube Views | N2: YouTube Likes | P2: TikTok Views | R2: Apple Music Playlist Count | T2: SiriusXM Spins
F4: Mean | G4: 6.6516229e+08 | H4: Mean | I4: 95863.866 | J4: Mean | K4: 67.596064 | L4: Mean | M4: 5.0413873e+08 | N4: Mean | O4: 3885864.1 | P4: Mean | Q4: 1.2818925e+09 | R4: Mean | S4: 79.787723 | T4: Mean | U4: 277.19306
F5: Standard Error | G5: 12447283 | H5: Standard Error | I5: 1691.2413 | J5: Standard Error | K5: 0.24655029 | L5: Standard Error | M5: 17377273 | N5: Standard Error | O5: 118147.9 | P5: Standard Error | Q5: 1.1624198e+08 | R5: Standard Error | S5: 1.7834823 | T5: Standard Error | U5: 12.685873
F6: Median | G6: 5.032422e+08 | H6: Median | I6: 73852 | J6: Median | K6: 69 | L6: Median | M6: 2.2129037e+08 | N6: Median | O6: 2131983 | P6: Median | Q6: 345053448 | R6: Median | S6: 53 | T6: Median | U6: 97
F7: Mode | G7: 860026452 | H7: Mode | I7: 212406 | J7: Mode | K7: 70 | L7: Mode | M7: 30913276 | N7: Mode | O7: 159791 | P7: Mode | Q7: 117505652 | R7: Mode | S7: 18 | T7: Mode | U7: 1
F8: Standard Deviation | G8: 5.7500519e+08 | H8: Standard Deviation | I8: 78127.296 | J8: Standard Deviation | K8: 11.389449 | L8: Standard Deviation | M8: 8.0274728e+08 | N8: Standard Deviation | O8: 5457870.3 | P8: Standard Deviation | Q8: 5.3698259e+09 | R8: Standard Deviation | S8: 82.388389 | T8: Standard Deviation | U8: 586.02692
F9: Sample Variance | G9: 3.3063097e+17 | H9: Sample Variance | I9: 6.1038744e+09 | J9: Sample Variance | K9: 129.71955 | L9: Sample Variance | M9: 6.4440319e+17 | N9: Sample Variance | O9: 2.9788348e+13 | P9: Sample Variance | Q9: 2.883503e+19 | R9: Sample Variance | S9: 6787.8466 | T9: Sample Variance | U9: 343427.55
F10: Kurtosis | G10: 3.0777639 | H10: Kurtosis | I10: 2.3425474 | J10: Kurtosis | K10: 10.784329 | L10: Kurtosis | M10: 87.549381 | N10: Kurtosis | O10: 24.922605 | P10: Kurtosis | Q10: 1181.7072 | R10: Kurtosis | S10: 8.9357591 | T10: Kurtosis | U10: 46.376826
F11: Skewness | G11: 1.5423746 | H11: Skewness | I11: 1.3874891 | J11: Skewness | K11: -2.4826717 | L11: Skewness | M11: 6.4528702 | N11: Skewness | O11: 3.9867483 | P11: Skewness | Q11: 30.578645 | R11: Skewness | S11: 2.3576202 | T11: Skewness | U11: 5.8328636
F12: Range | G12: 4281167358 | H12: Range | I12: 590081 | J12: Range | K12: 95 | L12: Range | M12: 16322745043 | N12: Range | O12: 62311008 | P12: Range | Q12: 214843956278 | R12: Range | S12: 858 | T12: Range | U12: 7097
F13: Minimum | G13: 301362 | H13: Minimum | I13: 311 | J13: Minimum | K13: 1 | L13: Minimum | M13: 11512 | N13: Minimum | O13: 171 | P13: Minimum | Q13: 312 | R13: Minimum | S13: 1 | T13: Minimum | U13: 1
F14: Maximum | G14: 4281468720 | H14: Maximum | I14: 590392 | J14: Maximum | K14: 96 | L14: Maximum | M14: 16322756555 | N14: Maximum | O14: 62311179 | P14: Maximum | Q14: 214843956590 | R14: Maximum | S14: 859 | T14: Maximum | U14: 7098
F15: Sum | G15: 1419456334356 | H15: Sum | I15: 204573489 | J15: Sum | K15: 144250 | L15: Sum | M15: 1075832040116 | N15: Sum | O15: 8292434065 | P15: Sum | Q15: 2735558496641 | R15: Sum | S15: 170267 | T15: Sum | U15: 591530
F16: Count | G16: 2134 | H16: Count | I16: 2134 | J16: Count | K16: 2134 | L16: Count | M16: 2134 | N16: Count | O16: 2134 | P16: Count | Q16: 2134 | R16: Count | S16: 2134 | T16: Count | U16: 2134
T20: Youtube Likes
I21: Spotify Streams | T21: Mean | U21: =O4 -> 3885864.1
I22: Mean | J22: =G4 -> 6.6516229e+08 | T22: Median | U22: =O6 -> 2131983
I23: Median | J23: =G6 -> 5.032422e+08 | T23: Std Dev | U23: =O8 -> 5457870.3
I24: Std Dev | J24: =G8 -> 5.7500519e+08 | T24: Skewness | U24: =O11 -> 3.9867483
I25: Skewness | J25: =G11 -> 1.5423746 | T25: Kurtosis | U25: =O10 -> 24.922605
I26: Kurtosis | J26: =G10 -> 3.0777639
I28: This variable is skewed right which is consistent with the higher mean than median and the positive skewness.
T33: Tik Tok Views
I34: Spotify Playlist Count | T34: Mean | U34: =Q4 -> 1.2818925e+09
I35: Mean | J35: =I4 -> 95863.866 | T35: Median | U35: =Q6 -> 345053448
I36: Median | J36: =I6 -> 73852 | T36: Std Dev | U36: =Q8 -> 5.3698259e+09
I37: Std Dev | J37: =I8 -> 78127.296 | T37: Skewness | U37: =Q11 -> 30.578645
I38: Skewness | J38: =I11 -> 1.3874891 | T38: Kurtosis | U38: =Q10 -> 1181.7072
I39: Kurtosis | J39: =I10 -> 2.3425474
T40: This variable is skewed right which is consistent with the higher mean than median and the positive skewness. This would mean that this variable is not normal.
I41: This variable is skewed right which is consistent with the higher mean than median and the positive skewness. This would mean that this variable is not normal.
I46: Spotify Popularity Count | T46: Apple Music Playlist Count
I47: Mean | J47: =K4 -> 67.596064 | T47: Mean | U47: =S4 -> 79.787723
I48: Median | J48: =K6 -> 69 | T48: Median | U48: =S6 -> 53
I49: Std Dev | J49: =K8 -> 11.389449 | T49: Std Dev | U49: =S8 -> 82.388389
I50: Skewness | J50: =K11 -> -2.4826717 | T50: Skewness | U50: =S11 -> 2.3576202
I51: Kurtosis | J51: =K10 -> 10.784329 | T51: Kurtosis | U51: =S10 -> 8.9357591
I53: This variable is skewed right which is consistent with the higher median than mean and the negative skewness. This would mean that this variable is not normal. | T53: This variable is skewed right which is consistent with the higher mean than median and the positive skewness. This would mean that this variable is not normal.
T58: SiriusXM Spins
I59: Youtube Views | T59: Mean | U59: =U4 -> 277.19306
...

Sheet Real-World Probability
A1: Probability Scenarios — Spotify Popularity Score
A3: Variable chosen:
A4: Why this variable:
A6: Distribution check
A7: Count (n)
A8: Mean
A9: Median
A10: Standard Deviation (sample)
A11: Skewness
A12: Conclusion
A14: Problem 1
A15: Problem statement:
... A22: Problem statement:
A23: Method used: | B23: Empirical distribution (percentile/relative frequency), because the variable is non-normal.
A24: Count where score < 50:
A25: Final probability answer:
A26: Explanation:
A28: Problem 3
A29: Problem statement:
A30: Method used: | B30: Empirical distribution (percentile/relative frequency), because the variable is non-normal.
A31: Count where 60 <= score <= 80:
A32: Final probability answer:
A33: Explanation:
A35: GenAI Usage & Citation
A36: How GenAI was used:
A37: Citation: | B37: Anthropic. (2026). Claude (Sonnet, July 26, 2026 version) [Large language model]. https://claude.ai

Sheet Probability Commentary
A1: Probability Commentary:
A2: Our eight continuous variables in the dataset did not come close to a normal distribution surprisingly, as the skewness ranged from -2.48 for certain variables to as high as 30.58 (for the Tiktok Views). Every variable also had a kurtosis score above 3, meaning heavy tails and clustering compared to the bell shaped curve of a normal distribution chart. With that being said, we need to hold a higher regard for the spotify popularity column in our cleaned data, even though we had initally gave less importance to this variable. Those scores still give us real world meaning to use towards practical decisions. We know that 5.7% of the total songs score above 80% in popularity, which sets a realistic standard for what data behind a successful song release should appear as and paints a picture for music labels developing a new artist. 82% of the total songs are in the popularity range of 60-80% range. A music label who has invested in an artist, should probably expect atleast 60% in terms of popularity rank in order to continue investing. Any artist who consistently misses the 60% mark may not be the "global star" the label was expecting at first. Anyone below 60% obviously has done a significant job by even making it to this chart, but may possibly be a "one hit wonder" or may not be able to reach their potential successfully.
